<mujoco model="two_link_manipulator">
    <default>
        <geom type="capsule" rgba="0.8 0.6 0.4 1" size="0.05" />
        <joint type="hinge" limited="true" range="-180 180" damping="1.0" />
    </default>

    <asset>
        <texture type="skybox" builtin="gradient" rgb1="1 1 1" rgb2="0.6 0.8 1" width="256" height="256" />
    </asset>

    <worldbody>
        <light pos="0 1 1" dir="0 -1 -1" diffuse="1 1 1" />
        
        <!-- Base -->
        <body name="base" pos="0 0 0">
            <!-- Link 1 -->
            <body name="link1" pos="0 0 0.05">
                <joint name="joint1" axis="0 0 1" />
                <geom name="link1_geom" fromto="0 0 0 1 0 0" />
                <site name="link1_end" pos="1 0 0" size="0.01" />

                <!-- Link 2 -->
                <body name="link2" pos="1 0 0">
                    <joint name="joint2" axis="0 0 1" />
                    <geom name="link2_geom" fromto="0 0 0 1 0 0" />
                    <site name="link2_end" pos="1 0 0" size="0.01" />
                </body>
            </body>
        </body>
    </worldbody>

    <tendon>
        <spatial name="tendon1" limited="true" range="0 2.0" width="0.005">
            <site site="link1_end" />
            <site site="link2_end" />
        </spatial>
    </tendon>

    <actuator>
        <motor joint="joint1" ctrlrange="-1 1" ctrllimited="true" />
        <motor joint="joint2" ctrlrange="-1 1" ctrllimited="true" />
    </actuator>
</mujoco>
