<mujoco model="two_link_planar_manipulator">
    <compiler angle="degree" />
    <option timestep="0.002" />
    <default>
        <joint damping="1.0" limited="true" range="-180 180" />
        <geom friction="0.8" />
    </default>

    <asset>
        <texture type="skybox" builtin="gradient" rgb1="1 1 1" rgb2="0.6 0.8 1" width="256" height="256" />
    </asset>

    <worldbody>
        <light pos="0 1 1" dir="0 -1 -1" diffuse="1 1 1" />

        <!-- Base -->
        <body name="base" pos="0 0 0">
            <!-- Link 1 -->
            <body name="link1" pos="0 0 0">
                <joint name="joint1" type="hinge" axis="0 0 1" />
                <geom name="link1_geom" type="capsule" fromto="0 0 0 1 0 0" size="0.05" rgba="1 0 0 1" />
                
                <!-- Link 2 -->
                <body name="link2" pos="1 0 0">
                    <joint name="joint2" type="hinge" axis="0 0 1" pos="0 0 0" />
                    <geom name="link2_geom" type="capsule" fromto="0 0 0 1 0 0" size="0.05" rgba="0 0 1 1" />
                </body>
            </body>
        </body>
    </worldbody>

    <actuator>
        <motor joint="joint1" ctrlrange="-1 1" ctrllimited="true" />
        <motor joint="joint2" ctrlrange="-1 1" ctrllimited="true" />
    </actuator>
</mujoco>
